Workbook

Sheet Main
A1: USD = | B1: 132
K2: Projection | L2: Aleppo | N2: Damascus
K3: Location | L3: 1 | M3: 1 | N3: 2 | O3: 2 | P3: 2
K4: Year | L4: 1 | M4: 2 | N4: 3 | O4: 4 | P4: 5
A6: App
A7: Commission Rate On Order | D7: 0.1 | K7: Number of Riders | L7: 50 | M7: 100 | N7: 250 | O7: 350 | P7: 350
A8: Delivery fee | D8: 150 | K8: Support | L8: 2 | M8: 4 | N8: 8 | O8: 8 | P8: 8
A9: Average order value | D9: 10 | K9: Marketing | L9: 2 | M9: 2 | N9: 6 | O9: 6 | P9: 6
A10: Average Orders per rider per day | D10: 15 | K10: Accountant | L10: 2 | M10: 2 | N10: 5 | O10: 5 | P10: 5
K11: IT Engineer | L11: 1 | M11: 1 | N11: 1 | O11: 1 | P11: 1
K12: Bike Mechanics | L12: =L3 -> 1 | M12: 2 | N12: 4 | O12: 4 | P12: 4
K13: Bike store manager | L13: =L3 -> 1 | M13: =M3 -> 1 | N13: 3 | O13: 3 | P13: 3
K15: Share with SyTRA | L15: 0 | M15: 500000 | N15: 1000000 | O15: 1500000 | P15: 1500000
K16: Number of Orders | L16: =L7*$D$10*30 -> 22500 | M16: =M7*$D$10*30 -> 45000 | N16: =N7*$D$10*30 -> 112500 | O16: =O7*$D$10*30 -> 157500 | P16: =P7*$D$10*30 -> 157500
K17: Monthly Revenue | L17: =L7*30*$D$10*($D$9*$D$7+$D$8/$B$1) -> 48068.182 | M17: =M7*30*$D$10*($D$9*$D$7+$D$8/$B$1) -> 96136.364 | N17: =N7*30*$D$10*($D$9*$D$7+$D$8/$B$1) -> 240340.91 | O17: =O7*30*$D$10*($D$9*$D$7+$D$8/$B$1) -> 336477.27 | P17: =P7*30*$D$10*($D$9*$D$7+$D$8/$B$1) -> 336477.27
A18: Initial Cost
A19: Investment Cycle | D19: 5
A20: Bikes | C20: =L7 -> 50 | D20: 1300 | L20: =-$D$20*L7/$D$19/12 -> -1083.3333 | M20: =-$D$20*M7/$D$19/12 -> -2166.6667 | N20: =-$D$20*N7/$D$19/12 -> -5416.6667 | O20: =-$D$20*O7/$D$19/12 -> -7583.3333 | P20: =-$D$20*P7/$D$19/12 -> -7583.3333
A21: Initial Marketing | D21: 5000 | L21: =-$D$21/$D$19/12*L3 -> -83.333333 | M21: =-$D$21/$D$19/12*M3 -> -83.333333 | N21: =-$D$21/$D$19/12*N3 -> -166.66667 | O21: =-$D$21/$D$19/12*O3 -> -166.66667 | P21: =-$D$21/$D$19/12*P3 -> -166.66667
A22: Office equipment | D22: 10000 | L22: =-$D$22/$D$19/12*L3 -> -166.66667 | M22: =-$D$22/$D$19/12*M3 -> -166.66667 | N22: =-$D$22/$D$19/12*N3 -> -333.33333 | O22: =-$D$22/$D$19/12*O3 -> -333.33333 | P22: =-$D$22/$D$19/12*P3 -> -333.33333
A23: bike space equipment | D23: 15000 | L23: =-$D$23/$D$19/12*L3 -> -250 | M23: =-$D$23/$D$19/12*M3 -> -250 | N23: =-$D$23/$D$19/12*N3 -> -500 | O23: =-$D$23/$D$19/12*O3 -> -500 | P23: =-$D$23/$D$19/12*P3 -> -500
A24: Platform Development | D24: 2000 | L24: =-$D$24/$D$19/12 -> -33.333333 | M24: =-$D$24/$D$19/12 -> -33.333333 | N24: =-$D$24/$D$19/12 -> -33.333333 | O24: =-$D$24/$D$19/12 -> -33.333333 | P24: =-$D$24/$D$19/12 -> -33.333333
A25: POS Devices | D25: 5000 | L25: =-$D$25/$D$19/12*L3 -> -83.333333 | M25: =-$D$25/$D$19/12*M3 -> -83.333333 | N25: =-$D$25/$D$19/12*N3 -> -166.66667 | O25: =-$D$25/$D$19/12*O3 -> -166.66667 | P25: =-$D$25/$D$19/12*P3 -> -166.66667
A26: Mobile Phones, uniforms & helmets | D26: =150+150 -> 300 | L26: =-$D$26*L7/$D$19/12 -> -250 | M26: =-$D$26*M7/$D$19/12 -> -500 | N26: =-$D$26*N7/$D$19/12 -> -1250 | O26: =-$D$26*O7/$D$19/12 -> -1750 | P26: =-$D$26*P7/$D$19/12 -> -1750
A27: Registration and Fees | C27: 500000 | D27: =C27/B1 -> 3787.8788 | L27: =-$D$27/$D$19/12 -> -63.131313 | M27: =-$D$27/$D$19/12 -> -63.131313 | N27: =-$D$27/$D$19/12 -> -63.131313 | O27: =-$D$27/$D$19/12 -> -63.131313 | P27: =-$D$27/$D$19/12 -> -63.131313
D28: =SUM(D21:D25)+D27+D20*C20+C20*D26 -> 120787.88 | E28: =D28-SUM(L31:L37)*12 -> 146625.76
A30: Annual Running cost
A31: Office rent | D31: 10000 | E31: year | L31: =-$D$31/12*L$3 -> -833.33333 | M31: =-$D$31/12*M$3 -> -833.33333 | N31: =-$D$31/12*N$3 -> -1666.6667 | O31: =-$D$31/12*O$3 -> -1666.6667 | P31: =-$D$31/12*P$3 -> -1666.6667
A32: bikes space rent | D32: 10000 | E32: year | L32: =-$D$32/12*L$3 -> -833.33333 | M32: =-$D$32/12*M$3 -> -833.33333 | N32: =-$D$32/12*N$3 -> -1666.6667 | O32: =-$D$32/12*O$3 -> -1666.6667 | P32: =-$D$32/12*P$3 -> -1666.6667
A33: Server Rent | D33: 300 | E33: year | L33: =-$D$33/12 -> -25 | M33: =-$D$33/12 -> -25 | N33: =-$D$33/12 -> -25 | O33: =-$D$33/12 -> -25 | P33: =-$D$33/12 -> -25
A34: App 3rd parties | D34: 500 | E34: domain, firebase, … | L34: =-$D$34/12 -> -41.666667 | M34: =-$D$34/12 -> -41.666667 | N34: =-$D$34/12 -> -41.666667 | O34: =-$D$34/12 -> -41.666667 | P34: =-$D$34/12 -> -41.666667
A35: annual GOV fees | C35: 5000 | D35: =C35/B1 -> 37.878788 | E35: year | L35: =-$D$35/12 -> -3.1565657 | M35: =-$D$35/12 -> -3.1565657 | N35: =-$D$35/12 -> -3.1565657 | O35: =-$D$35/12 -> -3.1565657 | P35: =-$D$35/12 -> -3.1565657
A36: Riders Insurance | D36: 100 | E36: year | L36: =-$D$36/12*L7 -> -416.66667 | M36: =-$D$36/12*M7 -> -833.33333 | N36: =-$D$36/12*N7 -> -2083.3333 | O36: =-$D$36/12*O7 -> -2916.6667 | P36: =-$D$36/12*P7 -> -2916.6667
A37: Bikes Insurance | D37: 0 | E37: year | L37: =-$D$37/12*L7 -> 0 | M37: =-$D$37/12*M7 -> 0 | N37: =-$D$37/12*N7 -> 0 | O37: =-$D$37/12*O7 -> 0 | P37: =-$D$37/12*P7 -> 0
A38: Share with SyTRA | L38: =-L15/$B$1/12 -> 0 | M38: =-M15/$B$1/12 -> -315.65657 | N38: =-N15/$B$1/12 -> -631.31313 | O38: =-O15/$B$1/12 -> -946.9697 | P38: =-P15/$B$1/12 -> -946.9697
D39: =SUM(D31:D35) -> 20837.879
A41: Monthly Running Costs
A42: Bills | D42: 500 | E42: Month | L42: =-$D$42*L3 -> -500 | M42: =-$D$42*M3 -> -500 | N42: =-$D$42*N3 -> -1000 | O42: =-$D$42*O3 -> -1000 | P42: =-$D$42*P3 -> -1000
A43: Marking | D43: 5000 | E43: year | L43: =-$D$43/12*L$3 -> -416.66667 | M43: =-$D$43/12*M$3 -> -416.66667 | N43: =-$D$43/12*N$3 -> -833.33333 | O43: =-$D$43/12*O$3 -> -833.33333 | P43: =-$D$43/12*P$3 -> -833.33333
A46: Salaries
...

Sheet Cash FLow
A8: Month | B8: Year | C8: Financing | D8: Initial Costs | E8: Annual Costs | F8: Monthly Costs | G8: Salaries | H8: Management Cash | I8: Tax | K8: Renvenu | M8: Operating Cash Flow | N8: Ending Cash
A9: 1 | B9: 1 | C9: 150000 | D9: =SUM(Main!L20:L27)*12*Main!D19 -> -120787.88 | E9: =SUM(Main!L31:L38)*12 -> -25837.879 | M9: =SUM(C9:K9) -> 3374.2424 | N9: =M9 -> 3374.2424
A10: 2 | B10: 1 | F10: =SUM(Main!$L$42:$L$43) -> -916.66667 | G10: =SUM(Main!$L$47:$L$53) -> -24184.091 | H10: -10000 | I10: =Main!$L$58+Main!$L$56 -> -2556.8182 | K10: =Main!$L$17 -> 48068.182 | M10: =SUM(C10:K10) -> 10410.606 | N10: =N9+M10 -> 13784.848
A11: 3 | B11: 1 | F11: =SUM(Main!$L$42:$L$43) -> -916.66667 | G11: =SUM(Main!$L$47:$L$53) -> -24184.091 | H11: -10000 | I11: =Main!$L$58+Main!$L$56 -> -2556.8182 | K11: =Main!$L$17 -> 48068.182 | M11: =SUM(C11:K11) -> 10410.606 | N11: =N10+M11 -> 24195.455
A12: 4 | B12: 1 | F12: =SUM(Main!$L$42:$L$43) -> -916.66667 | G12: =SUM(Main!$L$47:$L$53) -> -24184.091 | H12: -10000 | I12: =Main!$L$58+Main!$L$56 -> -2556.8182 | K12: =Main!$L$17 -> 48068.182 | M12: =SUM(C12:K12) -> 10410.606 | N12: =N11+M12 -> 34606.061
A13: 5 | B13: 1 | F13: =SUM(Main!$L$42:$L$43) -> -916.66667 | G13: =SUM(Main!$L$47:$L$53) -> -24184.091 | H13: -10000 | I13: =Main!$L$58+Main!$L$56 -> -2556.8182 | K13: =Main!$L$17 -> 48068.182 | M13: =SUM(C13:K13) -> 10410.606 | N13: =N12+M13 -> 45016.667
A14: 6 | B14: 1 | F14: =SUM(Main!$L$42:$L$43) -> -916.66667 | G14: =SUM(Main!$L$47:$L$53) -> -24184.091 | H14: -10000 | I14: =Main!$L$58+Main!$L$56 -> -2556.8182 | K14: =Main!$L$17 -> 48068.182 | M14: =SUM(C14:K14) -> 10410.606 | N14: =N13+M14 -> 55427.273
A15: 7 | B15: 1 | F15: =SUM(Main!$L$42:$L$43) -> -916.66667 | G15: =SUM(Main!$L$47:$L$53) -> -24184.091 | H15: -10000 | I15: =Main!$L$58+Main!$L$56 -> -2556.8182 | K15: =Main!$L$17 -> 48068.182 | M15: =SUM(C15:K15) -> 10410.606 | N15: =N14+M15 -> 65837.879
A16: 8 | B16: 1 | F16: =SUM(Main!$L$42:$L$43) -> -916.66667 | G16: =SUM(Main!$L$47:$L$53) -> -24184.091 | H16: -10000 | I16: =Main!$L$58+Main!$L$56 -> -2556.8182 | K16: =Main!$L$17 -> 48068.182 | M16: =SUM(C16:K16) -> 10410.606 | N16: =N15+M16 -> 76248.485
A17: 9 | B17: 1 | F17: =SUM(Main!$L$42:$L$43) -> -916.66667 | G17: =SUM(Main!$L$47:$L$53) -> -24184.091 | H17: -10000 | I17: =Main!$L$58+Main!$L$56 -> -2556.8182 | K17: =Main!$L$17 -> 48068.182 | M17: =SUM(C17:K17) -> 10410.606 | N17: =N16+M17 -> 86659.091
A18: 10 | B18: 1 | F18: =SUM(Main!$L$42:$L$43) -> -916.66667 | G18: =SUM(Main!$L$47:$L$53) -> -24184.091 | H18: -10000 | I18: =Main!$L$58+Main!$L$56 -> -2556.8182 | K18: =Main!$L$17 -> 48068.182 | M18: =SUM(C18:K18) -> 10410.606 | N18: =N17+M18 -> 97069.697
A19: 11 | B19: 1 | F19: =SUM(Main!$L$42:$L$43) -> -916.66667 | G19: =SUM(Main!$L$47:$L$53) -> -24184.091 | H19: -10000 | I19: =Main!$L$58+Main!$L$56 -> -2556.8182 | K19: =Main!$L$17 -> 48068.182 | M19: =SUM(C19:K19) -> 10410.606 | N19: =N18+M19 -> 107480.3
A20: 12 | B20: 1 | D20: =SUM(Main!M20:M27)*12*Main!D19-D9+Main!M38*12 -> -83787.879 | E20: =SUM(Main!M31:M38)*12 -> -34625.758 | F20: =SUM(Main!$L$42:$L$43) -> -916.66667 | G20: =SUM(Main!$L$47:$L$53) -> -24184.091 | H20: -10000 | I20: =Main!$L$58+Main!$L$56 -> -2556.8182 | K20: =Main!$L$17 -> 48068.182 | M20: =SUM(C20:K20) -> -108003.03 | N20: =N19+M20 -> -522.72727
A21: 13 | B21: 2 | F21: =SUM(Main!$M$42:$M$43) -> -916.66667 | G21: =SUM(Main!$M$47:$M$53) -> -45668.182 | H21: -10000 | I21: =Main!$M$58+Main!$M$56 -> -5113.6364 | K21: =Main!$M$17 -> 96136.364 | M21: =SUM(C21:K21) -> 34437.879 | N21: =N20+M21 -> 33915.152
A22: 14 | B22: 2 | F22: =SUM(Main!$M$42:$M$43) -> -916.66667 | G22: =SUM(Main!$M$47:$M$53) -> -45668.182 | H22: -10000 | I22: =Main!$M$58+Main!$M$56 -> -5113.6364 | K22: =Main!$M$17 -> 96136.364 | M22: =SUM(C22:K22) -> 34437.879 | N22: =N21+M22 -> 68353.03
A23: 15 | B23: 2 | F23: =SUM(Main!$M$42:$M$43) -> -916.66667 | G23: =SUM(Main!$M$47:$M$53) -> -45668.182 | H23: -10000 | I23: =Main!$M$58+Main!$M$56 -> -5113.6364 | K23: =Main!$M$17 -> 96136.364 | M23: =SUM(C23:K23) -> 34437.879 | N23: =N22+M23 -> 102790.91
A24: 16 | B24: 2 | F24: =SUM(Main!$M$42:$M$43) -> -916.66667 | G24: =SUM(Main!$M$47:$M$53) -> -45668.182 | H24: -10000 | I24: =Main!$M$58+Main!$M$56 -> -5113.6364 | K24: =Main!$M$17 -> 96136.364 | M24: =SUM(C24:K24) -> 34437.879 | N24: =N23+M24 -> 137228.79
A25: 17 | B25: 2 | F25: =SUM(Main!$M$42:$M$43) -> -916.66667 | G25: =SUM(Main!$M$47:$M$53) -> -45668.182 | H25: -10000 | I25: =Main!$M$58+Main!$M$56 -> -5113.6364 | K25: =Main!$M$17 -> 96136.364 | M25: =SUM(C25:K25) -> 34437.879 | N25: =N24+M25 -> 171666.67
A26: 18 | B26: 2 | F26: =SUM(Main!$M$42:$M$43) -> -916.66667 | G26: =SUM(Main!$M$47:$M$53) -> -45668.182 | H26: -10000 | I26: =Main!$M$58+Main!$M$56 -> -5113.6364 | K26: =Main!$M$17 -> 96136.364 | M26: =SUM(C26:K26) -> 34437.879 | N26: =N25+M26 -> 206104.55
A27: 19 | B27: 2 | F27: =SUM(Main!$M$42:$M$43) -> -916.66667 | G27: =SUM(Main!$M$47:$M$53) -> -45668.182 | H27: -10000 | I27: =Main!$M$58+Main!$M$56 -> -5113.6364 | K27: =Main!$M$17 -> 96136.364 | M27: =SUM(C27:K27) -> 34437.879 | N27: =N26+M27 -> 240542.42
A28: 20 | B28: 2 | F28: =SUM(Main!$M$42:$M$43) -> -916.66667 | G28: =SUM(Main!$M$47:$M$53) -> -45668.182 | H28: -10000 | I28: =Main!$M$58+Main!$M$56 -> -5113.6364 | K28: =Main!$M$17 -> 96136.364 | M28: =SUM(C28:K28) -> 34437.879 | N28: =N27+M28 -> 274980.3
A29: 21 | B29: 2 | F29: =SUM(Main!$M$42:$M$43) -> -916.66667 | G29: =SUM(Main!$M$47:$M$53) -> -45668.182 | H29: -10000 | I29: =Main!$M$58+Main!$M$56 -> -5113.6364 | K29: =Main!$M$17 -> 96136.364 | M29: =SUM(C29:K29) -> 34437.879 | N29: =N28+M29 -> 309418.18
A30: 22 | B30: 2 | F30: =SUM(Main!$M$42:$M$43) -> -916.66667 | G30: =SUM(Main!$M$47:$M$53) -> -45668.182 | H30: -10000 | I30: =Main!$M$58+Main!$M$56 -> -5113.6364 | K30: =Main!$M$17 -> 96136.364 | M30: =SUM(C30:K30) -> 34437.879 | N30: =N29+M30 -> 343856.06
A31: 23 | B31: 2 | F31: =SUM(Main!$M$42:$M$43) -> -916.66667 | G31: =SUM(Main!$M$47:$M$53) -> -45668.182 | H31: -10000 | I31: =Main!$M$58+Main!$M$56 -> -5113.6364 | K31: =Main!$M$17 -> 96136.364 | M31: =SUM(C31:K31) -> 34437.879 | N31: =N30+M31 -> 378293.94
A32: 24 | B32: 2 | D32: =SUM(Main!N20:N27)*12*Main!D19-D9-D20+Main!N38*12 -> -278787.88 | E32: =SUM(Main!N31:N38)*12 -> -73413.636 | F32: =SUM(Main!$M$42:$M$43) -> -916.66667 | G32: =SUM(Main!$M$47:$M$53) -> -45668.182 | H32: -10000 | I32: =Main!$M$58+Main!$M$56 -> -5113.6364 | K32: =Main!$M$17 -> 96136.364 | M32: =SUM(C32:K32) -> -317763.64 | N32: =N31+M32 -> 60530.303
A33: 25 | B33: 3 | F33: =SUM(Main!$N$42:$N$43) -> -1833.3333 | G33: =SUM(Main!$N$47:$N$53) -> -112720.45 | H33: -10000 | I33: =Main!$N$58+Main!$N$56 -> -12784.091 | K33: =Main!$N$17 -> 240340.91 | M33: =SUM(C33:K33) -> 103003.03 | N33: =N32+M33 -> 163533.33
A34: 26 | B34: 3 | F34: =SUM(Main!$N$42:$N$43) -> -1833.3333 | G34: =SUM(Main!$N$47:$N$53) -> -112720.45 | H34: -10000 | I34: =Main!$N$58+Main!$N$56 -> -12784.091 | K34: =Main!$N$17 -> 240340.91 | M34: =SUM(C34:K34) -> 103003.03 | N34: =N33+M34 -> 266536.36
A35: 27 | B35: 3 | F35: =SUM(Main!$N$42:$N$43) -> -1833.3333 | G35: =SUM(Main!$N$47:$N$53) -> -112720.45 | H35: -10000 | I35: =Main!$N$58+Main!$N$56 -> -12784.091 | K35: =Main!$N$17 -> 240340.91 | M35: =SUM(C35:K35) -> 103003.03 | N35: =N34+M35 -> 369539.39
A36: 28 | B36: 3 | F36: =SUM(Main!$N$42:$N$43) -> -1833.3333 | G36: =SUM(Main!$N$47:$N$53) -> -112720.45 | H36: -10000 | I36: =Main!$N$58+Main!$N$56 -> -12784.091 | K36: =Main!$N$17 -> 240340.91 | M36: =SUM(C36:K36) -> 103003.03 | N36: =N35+M36 -> 472542.42
A37: 29 | B37: 3 | F37: =SUM(Main!$N$42:$N$43) -> -1833.3333 | G37: =SUM(Main!$N$47:$N$53) -> -112720.45 | H37: -10000 | I37: =Main!$N$58+Main!$N$56 -> -12784.091 | K37: =Main!$N$17 -> 240340.91 | M37: =SUM(C37:K37) -> 103003.03 | N37: =N36+M37 -> 575545.45
A38: 30 | B38: 3 | F38: =SUM(Main!$N$42:$N$43) -> -1833.3333 | G38: =SUM(Main!$N$47:$N$53) -> -112720.45 | H38: -10000 | I38: =Main!$N$58+Main!$N$56 -> -12784.091 | K38: =Main!$N$17 -> 240340.91 | M38: =SUM(C38:K38) -> 103003.03 | N38: =N37+M38 -> 678548.48
A39: 31 | B39: 3 | F39: =SUM(Main!$N$42:$N$43) -> -1833.3333 | G39: =SUM(Main!$N$47:$N$53) -> -112720.45 | H39: -10000 | I39: =Main!$N$58+Main!$N$56 -> -12784.091 | K39: =Main!$N$17 -> 240340.91 | M39: =SUM(C39:K39) -> 103003.03 | N39: =N38+M39 -> 781551.52
A40: 32 | B40: 3 | F40: =SUM(Main!$N$42:$N$43) -> -1833.3333 | G40: =SUM(Main!$N$47:$N$53) -> -112720.45 | H40: -10000 | I40: =Main!$N$58+Main!$N$56 -> -12784.091 | K40: =Main!$N$17 -> 240340.91 | M40: =SUM(C40:K40) -> 103003.03 | N40: =N39+M40 -> 884554.55
A41: 33 | B41: 3 | F41: =SUM(Main!$N$42:$N$43) -> -1833.3333 | G41: =SUM(Main!$N$47:$N$53) -> -112720.45 | H41: -10000 | I41: =Main!$N$58+Main!$N$56 -> -12784.091 | K41: =Main!$N$17 -> 240340.91 | M41: =SUM(C41:K41) -> 103003.03 | N41: =N40+M41 -> 987557.58
A42: 34 | B42: 3 | F42: =SUM(Main!$N$42:$N$43) -> -1833.3333 | G42: =SUM(Main!$N$47:$N$53) -> -112720.45 | H42: -10000 | I42: =Main!$N$58+Main!$N$56 -> -12784.091 | K42: =Main!$N$17 -> 240340.91 | M42: =SUM(C42:K42) -> 103003.03 | N42: =N41+M42 -> 1090560.6
A43: 35 | B43: 3 | F43: =SUM(Main!$N$42:$N$43) -> -1833.3333 | G43: =SUM(Main!$N$47:$N$53) -> -112720.45 | H43: -10000 | I43: =Main!$N$58+Main!$N$56 -> -12784.091 | K43: =Main!$N$17 -> 240340.91 | M43: =SUM(C43:K43) -> 103003.03 | N43: =N42+M43 -> 1193563.6
A44: 36 | B44: 3 | D44: =SUM(Main!O20:O27)*12*Main!D19-D9-D20-D32+Main!O38*12 -> -163787.88 | E44: =SUM(Main!O31:O38)*12 -> -87201.515 | F44: =SUM(Main!$N$42:$N$43) -> -1833.3333 | G44: =SUM(Main!$N$47:$N$53) -> -112720.45 | H44: -10000 | I44: =Main!$N$58+Main!$N$56 -> -12784.091 | K44: =Main!$N$17 -> 240340.91 | M44: =SUM(C44:K44) -> -147986.36 | N44: =N43+M44 -> 1045577.3
A45: 37 | B45: 4 | F45: =SUM(Main!$O$42:$O$43) -> -1833.3333 | G45: =SUM(Main!$O$47:$O$53) -> -153288.64 | H45: -10000 | I45: =Main!$O$58+Main!$O$56 -> -17897.727 | K45: =Main!$O$17 -> 336477.27 | M45: =SUM(C45:K45) -> 153457.58 | N45: =N44+M45 -> 1199034.8
A46: 38 | B46: 4 | F46: =SUM(Main!$O$42:$O$43) -> -1833.3333 | G46: =SUM(Main!$O$47:$O$53) -> -153288.64 | H46: -10000 | I46: =Main!$O$58+Main!$O$56 -> -17897.727 | K46: =Main!$O$17 -> 336477.27 | M46: =SUM(C46:K46) -> 153457.58 | N46: =N45+M46 -> 1352492.4
A47: 39 | B47: 4 | F47: =SUM(Main!$O$42:$O$43) -> -1833.3333 | G47: =SUM(Main!$O$47:$O$53) -> -153288.64 | H47: -10000 | I47: =Main!$O$58+Main!$O$56 -> -17897.727 | K47: =Main!$O$17 -> 336477.27 | M47: =SUM(C47:K47) -> 153457.58 | N47: =N46+M47 -> 1505950
...

Sheet Rider Salary Calculation
A10: USD Rate | B10: =Main!B1 -> 132 | D10: # Orders | E10: 10 | F10: 15 | G10: 20
A11: Delivery fee | B11: =Main!D8 -> 150 | D11: Salary + Bonus | E11: =E10*30*$B$11/$B$10*$B$13+$B$12 -> 320.45455 | F11: =F10*30*$B$11/$B$10*$B$13+$B$12 -> 405.68182 | G11: =G10*30*$B$11/$B$10*$B$13+$B$12 -> 490.90909
A12: Base | B12: 150
A13: % | B13: 0.5
